Workbook

Sheet Overview
B2: Abu Dhabi Marathon 2026 — Training Plan
B4: Race | C4: Abu Dhabi Marathon
B5: Race date | C5: 46368
B6: Training start | C6: 46225
B7: Goal | C7: PRIMARY: finish healthy (first marathon). Current time goal: sub-3:50 (~5:27/km). Ceiling if fitness clearly supports it: 3:30 — never faster. Next goal review: after Wk13 HM time trial (17 Oct).
B8: Today | C8: =TODAY() -> 46232
B9: Days to race | C9: =C5-C8 -> 136
B10: Weeks to race | C10: =ROUNDUP(C9/7,0) -> 20
B12: Pace zones (CALIBRATED after Wk1 5K time trial 24 Jul 2026: 5 km in 23:20 @ 4:40/km, RPE 7. Conservative interpretation. Recheck at the Wk13 half-marathon time trial on Sat 17 Oct.)
B13: Zone | C13: Pace (min/km) | D13: Notes
B14: Easy | C14: 6:10 - 6:40 | D14: Conversational effort, most easy runs and long-run pace
B15: Marathon pace (MP) | C15: 5:23 - 5:30 | D15: Goal race pace
B16: Tempo | C16: 5:05 - 5:20 | D16: Sustained "comfortably hard" effort
B17: Intervals | C17: 4:30 - 4:45 | D17: Repeats, with jog recovery between
B19: Phases
B20: Phase | C20: Weeks | D20: Dates | E20: Focus
B21: Base building | C21: 1-7 | D21: 22 Jul - 5 Sep | E21: Establish running habit + gym routine, keep football
B22: Aerobic build | C22: 8-13 | D22: 6 Sep - 17 Oct | E22: Add tempo/MP segments; Wk13 half-marathon time trial
B23: Peak | C23: 14-18 | D23: 18 Oct - 21 Nov | E23: Highest volume, MP-specific long runs, intervals
B24: Taper | C24: 19-21 | D24: 22 Nov - 12 Dec | E24: Volume down, stay sharp, RACE 12 Dec
B26: Deload weeks: 5, 10, 14 (volume cut ~20-25%). Checkpoints: Wk1 baseline 5K, Wk13 half-marathon time trial.
B28: Yellow cells are yours to edit (pace zones as you calibrate them). Everything else on this sheet is a formula or fixed reference.

Sheet Weekly Plan
A1: Week | B1: Phase | C1: Deload | D1: Date | E1: Day | F1: Session Type | G1: Discipline | H1: Planned (km) | I1: Planned Pace/Effort | J1: Planned Focus | K1: Workout | L1: Completed (Y/N) | M1: Actual (km) | N1: Actual Duration (h:mm:ss) | O1: Actual Pace (mm:ss/km) | P1: RPE (1-10) | Q1: Felt | R1: Notes
A2: 1 | B2: Base building | C2: No | D2: 46225 | E2: Wednesday | F2: Gym | G2: Push (chest) | I2: - | J2: Push day A + easy shakeout run | K2: - | L2: Y | M2: NA | N2: NA | O2: NA | P2: 5 | Q2: Great
A3: 1 | B3: Base building | C3: No | D3: 46225 | E3: Wednesday | F3: Run | G3: Easy | H3: 4 | I3: Easy | J3: First easy run of the plan - conversational pace, walk breaks welcome | K3: Easy run | L3: Y | M3: 4 | N3: 0:24:00 | O3: 0.25 | P3: 4 | Q3: Great
A4: 1 | B4: Base building | C4: No | D4: 46226 | E4: Thursday | F4: Run | G4: Easy | H4: 4 | I4: Easy | J4: Easy effort, focus on consistent light footstrike | K4: Easy run | L4: Y | M4: 4 | N4: 0:24:00 | O4: 0.25 | P4: 4 | Q4: Good | R4: Paired with shoulder training
A5: 1 | B5: Base building | C5: No | D5: 46227 | E5: Friday | F5: Run | G5: Baseline Time Trial | H5: 5 | I5: Max effort (5K) | J5: Baseline 5K time trial - run at a hard, sustainable effort. Result calibrates all pace zones on the Overview sheet | K5: Baseline 5K time trial | L5: Y | M5: 5 | N5: 0:23:20 | O5: 0.0032407407 | P5: 7 | Q5: Good
A6: 1 | B6: Base building | C6: No | D6: 46227 | E6: Friday | F6: Gym | G6: Pull (back) | I6: - | J6: Pull day A + time trial | K6: - | L6: N
A7: 1 | B7: Base building | C7: No | D7: 46228 | E7: Saturday | F7: Run | G7: Long run | H7: 8 | I7: Easy | J7: First long run - run/walk is fine, just build time on feet | K7: Long run - easy | L7: Y | M7: 8 | N7: 4:00:00 | O7: 0.5 | P7: 1 | Q7: Good | R7: Walked while playing Golf
A8: 2 | B8: Base building | C8: No | D8: 46229 | E8: Sunday | F8: Rest | G8: Full rest | I8: - | J8: Recovery after Saturday's long run | K8: - | L8: Y | Q8: Great
A9: 2 | B9: Base building | C9: No | D9: 46230 | E9: Monday | F9: Gym | G9: Legs | I9: - | J9: Legs day + easy run | K9: -
A10: 2 | B10: Base building | C10: No | D10: 46230 | E10: Monday | F10: Run | G10: Easy | H10: 4.5 | I10: Easy | J10: Easy/conversational pace | K10: Easy run | L10: Y | M10: 8 | N10: 1:30:00 | O10: 0.45833333 | P10: 7 | Q10: Tired | R10: Replaced by football game
A11: 2 | B11: Base building | C11: No | D11: 46231 | E11: Tuesday | F11: Run | G11: Tempo | H11: 5.5 | I11: Tempo | J11: Continuous tempo block within the session, building duration through the phase | K11: 12-min tempo | L11: Y | M11: 6 | N11: 0:33:00 | O11: 0.22916667 | P11: 6 | Q11: Tired
A12: 2 | B12: Base building | C12: No | D12: 46232 | E12: Wednesday | F12: Gym | G12: Pull (back) | I12: - | J12: Pull day + easy run | K12: -
A13: 2 | B13: Base building | C13: No | D13: 46232 | E13: Wednesday | F13: Run | G13: Easy | H13: 4.5 | I13: Easy | J13: Easy/conversational pace | K13: Easy run
A14: 2 | B14: Base building | C14: No | D14: 46233 | E14: Thursday | F14: Run | G14: Medium-long | H14: 5 | I14: Steady | J14: Medium-long / steady run | K14: Medium-long - steady
A15: 2 | B15: Base building | C15: No | D15: 46234 | E15: Friday | F15: Gym | G15: Push (chest) | I15: - | J15: Push day | K15: -
A16: 2 | B16: Base building | C16: No | D16: 46235 | E16: Saturday | F16: Run | G16: Long run | H16: 10 | I16: Easy | J16: Long run - mostly easy effort, this is about time on feet and aerobic endurance | K16: Long run - easy
A17: 3 | B17: Base building | C17: No | D17: 46236 | E17: Sunday | F17: Rest | G17: Full rest | I17: - | J17: Recovery after Saturday's long run | K17: -
A18: 3 | B18: Base building | C18: No | D18: 46237 | E18: Monday | F18: Gym | G18: Legs | I18: - | J18: Legs day + easy run | K18: -
A19: 3 | B19: Base building | C19: No | D19: 46237 | E19: Monday | F19: Run | G19: Easy | H19: 4.5 | I19: Easy | J19: Easy/conversational pace | K19: Easy run
A20: 3 | B20: Base building | C20: No | D20: 46238 | E20: Tuesday | F20: Run | G20: Intervals | H20: 5.5 | I20: Intervals | J20: Repeats (e.g. 400-1000m) with equal-time jog recovery, building reps through the phase | K20: 6 x 400 m
A21: 3 | B21: Base building | C21: No | D21: 46239 | E21: Wednesday | F21: Gym | G21: Pull (back) | I21: - | J21: Pull day + easy run | K21: -
A22: 3 | B22: Base building | C22: No | D22: 46239 | E22: Wednesday | F22: Run | G22: Easy | H22: 4.5 | I22: Easy | J22: Easy/conversational pace | K22: Easy run
A23: 3 | B23: Base building | C23: No | D23: 46240 | E23: Thursday | F23: Run | G23: Medium-long | H23: 6 | I23: Steady | J23: Medium-long / steady run | K23: Medium-long - steady
A24: 3 | B24: Base building | C24: No | D24: 46241 | E24: Friday | F24: Gym | G24: Push (chest) | I24: - | J24: Push day | K24: -
A25: 3 | B25: Base building | C25: No | D25: 46242 | E25: Saturday | F25: Run | G25: Long run | H25: 12 | I25: Easy | J25: Long run - mostly easy effort, this is about time on feet and aerobic endurance | K25: Long run - easy
A26: 4 | B26: Base building | C26: No | D26: 46243 | E26: Sunday | F26: Rest | G26: Full rest | I26: - | J26: Recovery after Saturday's long run | K26: -
A27: 4 | B27: Base building | C27: No | D27: 46244 | E27: Monday | F27: Gym | G27: Legs | I27: - | J27: Legs day + easy run | K27: -
A28: 4 | B28: Base building | C28: No | D28: 46244 | E28: Monday | F28: Run | G28: Easy | H28: 4.5 | I28: Easy | J28: Easy/conversational pace | K28: Easy run
A29: 4 | B29: Base building | C29: No | D29: 46245 | E29: Tuesday | F29: Run | G29: Tempo | H29: 5.5 | I29: Tempo | J29: Continuous tempo block within the session, building duration through the phase | K29: 15-min tempo
A30: 4 | B30: Base building | C30: No | D30: 46246 | E30: Wednesday | F30: Gym | G30: Pull (back) | I30: - | J30: Pull day + easy run | K30: -
A31: 4 | B31: Base building | C31: No | D31: 46246 | E31: Wednesday | F31: Run | G31: Easy | H31: 4.5 | I31: Easy | J31: Easy/conversational pace | K31: Easy run
A32: 4 | B32: Base building | C32: No | D32: 46247 | E32: Thursday | F32: Run | G32: Medium-long | H32: 6 | I32: Steady | J32: Medium-long / steady run | K32: Medium-long - steady
A33: 4 | B33: Base building | C33: No | D33: 46248 | E33: Friday | F33: Gym | G33: Push (chest) | I33: - | J33: Push day | K33: -
A34: 4 | B34: Base building | C34: No | D34: 46249 | E34: Saturday | F34: Run | G34: Long run | H34: 14 | I34: Easy | J34: Long run - mostly easy effort, this is about time on feet and aerobic endurance | K34: Long run - easy
A35: 5 | B35: Base building | C35: Yes | D35: 46250 | E35: Sunday | F35: Rest | G35: Full rest | I35: - | J35: Recovery after Saturday's long run - deload week, prioritize sleep/nutrition | K35: -
A36: 5 | B36: Base building | C36: Yes | D36: 46251 | E36: Monday | F36: Gym | G36: Legs | I36: - | J36: Legs day + easy run | K36: -
A37: 5 | B37: Base building | C37: Yes | D37: 46251 | E37: Monday | F37: Run | G37: Easy | H37: 3.5 | I37: Easy | J37: Easy/conversational pace | K37: Easy run
A38: 5 | B38: Base building | C38: Yes | D38: 46252 | E38: Tuesday | F38: Run | G38: Intervals | H38: 4.5 | I38: Intervals | J38: Deload week - shorten reps/tempo block by ~25%, same structure | K38: 5 x 400 m (deload)
A39: 5 | B39: Base building | C39: Yes | D39: 46253 | E39: Wednesday | F39: Gym | G39: Pull (back) | I39: - | J39: Pull day + easy run | K39: -
A40: 5 | B40: Base building | C40: Yes | D40: 46253 | E40: Wednesday | F40: Run | G40: Easy | H40: 3.5 | I40: Easy | J40: Easy/conversational pace | K40: Easy run
...

Sheet Workouts
B2: Workout Library
B3: Named, spelled-out sessions referenced by the 'Workout' column on the Weekly Plan. All paces are in min/km, CALIBRATED to the Wk1 5K baseline (24 Jul 2026: 4:40/km, RPE 7) with a conservative interpretation. MP band shifted to the sub-3:50 goal (5:27/km). Recheck after the Wk13 half-marathon time trial.
B5: Workout | C5: Type | D5: Warm-up | E5: Main set | F5: Cool-down | G5: Target pace (min/km) | H5: Approx. km | I5: Notes
B6: EASY / STEADY / LONG (aerobic base - reference by distance on the plan)
B7: Easy run | C7: Easy | D7: - | E7: Whole run at easy, conversational effort. Nose-breathing pace; walk breaks are fine. | F7: - | G7: 6:10-6:40 | H7: per plan | I7: Most Mon/Wed/Thu runs. Effort, not pace, is the target.
B8: Medium-long - steady | C8: Steady | D8: 1 km easy | E8: Steady aerobic running - a touch faster than easy but still comfortable. | F8: included | G8: 5:50-6:10 | H8: per plan | I8: Friday medium-long runs in the Base phase.
B9: Medium-long + MP finish | C9: Steady + MP | D9: 1-2 km easy | E9: Steady, then finish the last 3-4 km at marathon pace. | F9: 0.5 km easy | G9: steady 5:50-6:10, MP 5:23-5:30 | H9: per plan | I9: Friday runs from Wk8 on. Teaches goal pace on tired-ish legs.
B10: Long run - easy | C10: Long | D10: - | E10: Continuous easy running, all about time on feet and aerobic endurance. | F10: - | G10: 6:15-6:45 | H10: per plan | I10: Base-phase long runs (Wk1-12). Fuel and hydrate on anything over ~90 min.
B11: Long run + MP segments | C11: Long + MP | D11: 3-4 km easy | E11: Easy, with 2-4 blocks of 3-5 km at marathon pace spread through the run; easy between. | F11: 1 km easy | G11: easy 6:15-6:45, MP 5:23-5:30 | H11: per plan | I11: Peak-phase long runs (Wk14-20). The key marathon-specific sessions.
B12: TEMPO (sustained 'comfortably hard' - Tuesday quality)
B13: 12-min tempo | C13: Tempo | D13: 1.5 km easy | E13: 12 min continuous @ tempo. | F13: 1.9 km easy | G13: tempo ~5:10 | H13: 5.5 | I13: Wk2. First tempo - err on the easier side of the range.
B14: 15-min tempo | C14: Tempo | D14: 1.5 km easy | E14: 15 min continuous @ tempo. | F14: 1.4 km easy | G14: tempo ~5:10 | H14: 5.5 | I14: Wk4.
B15: 18-min tempo | C15: Tempo | D15: 1.3 km easy | E15: 18 min continuous @ tempo. | F15: 1.0 km easy | G15: tempo ~5:10 | H15: 5.5 | I15: Wk6.
B16: 2 x 10-min tempo | C16: Tempo (broken) | D16: 1.5 km easy | E16: 2 x 10 min @ tempo, 2 min easy jog between. | F16: 1.3 km easy | G16: tempo ~5:10, jog 6:10-6:40 | H16: 6.5 | I16: Wk8. Breaking it up lets you hold slightly better quality.
B17: 18-min tempo (deload) | C17: Tempo | D17: 1.0 km easy | E17: 18 min continuous @ easy end of tempo. | F17: 0.8 km easy | G17: tempo 5:20-5:25 | H17: 5 | I17: Wk10 deload - hold back ~25%.
B18: 25-min tempo | C18: Tempo | D18: 1.2 km easy | E18: 25 min continuous @ tempo. | F18: 0.9 km easy | G18: tempo ~5:10 | H18: 6.5 | I18: Wk12. Longest continuous tempo of the build.
B19: 2 x 10-min tempo (deload) | C19: Tempo (broken) | D19: 1.5 km easy | E19: 2 x 10 min @ easy-tempo, 2 min jog between. | F19: 1.0 km easy | G19: tempo 5:20-5:25 | H19: 6 | I19: Wk14 deload - keep it controlled.
B20: 3 x 8-min cruise | C20: Tempo/MP | D20: 2.0 km easy | E20: 3 x 8 min @ marathon-to-tempo pace, 90 s jog between. | F20: 1.5 km easy | G20: 5:23-5:32 (MP-tempo) | H20: 7.5 | I20: Wk16. Bridges tempo and marathon pace.
B21: 3 x 10-min tempo | C21: Tempo (broken) | D21: 1.5 km easy | E21: 3 x 10 min @ tempo, 2 min jog between. | F21: 1.0 km easy | G21: tempo ~5:10 | H21: 7.5 | I21: Wk18. Biggest tempo volume of the plan.
B22: 15-min tempo (sharpener) | C22: Tempo | D22: 1.5 km easy | E22: 15 min @ tempo to stay sharp. | F22: 1.0 km easy | G22: tempo ~5:10 | H22: 5 | I22: Wk20 taper - short and crisp, do not overreach.
B23: INTERVALS (faster reps with jog recovery - Tuesday quality)
B24: 6 x 400 m | C24: Intervals | D24: 1.5 km easy + 3 strides | E24: 6 x 400 m fast, 200 m (~90 s) easy jog between. | F24: 1.0 km easy | G24: reps 4:30-4:40, jog 6:10-6:40 | H24: 5.5 | I24: Wk3. Short and snappy; stay smooth, not sprinting.
B25: 5 x 400 m (deload) | C25: Intervals | D25: 1.2 km easy + 2 strides | E25: 5 x 400 m controlled, 200 m easy jog between. | F25: 0.9 km easy | G25: reps 4:35-4:45 | H25: 4.5 | I25: Wk5 deload - fewer reps, controlled effort.
B26: 6 x 500 m | C26: Intervals | D26: 1.2 km easy + 3 strides | E26: 6 x 500 m, 200 m easy jog between. | F26: 0.8 km easy | G26: reps 4:35-4:45 | H26: 5.5 | I26: Wk7.
B27: 5 x 800 m | C27: Intervals | D27: 1.5 km easy + 3 strides | E27: 5 x 800 m, 2 min easy jog between. | F27: 1.0 km easy | G27: reps 4:40-4:50 | H27: 6.5 | I27: Wk9. Longer reps - settle into a rhythm.
B28: 6 x 600 m | C28: Intervals | D28: 1.5 km easy + 3 strides | E28: 6 x 600 m, 200 m easy jog between. | F28: 0.8 km easy | G28: reps 4:40-4:50 | H28: 6.5 | I28: Wk11.
B29: 10 x 2 min | C29: Intervals (VO2) | D29: 2.0 km easy + 3 strides | E29: 10 x 2 min hard, 2 min easy jog between. | F29: 1.5 km easy | G29: reps 4:30-4:45 | H29: 7.5 | I29: Wk15. Classic VO2 session - by feel this is ~5K effort.
B30: 5 x 1 km | C30: Intervals | D30: 1.5 km easy + 3 strides | E30: 5 x 1 km, 2 min easy jog between. | F30: 1.0 km easy | G30: reps 4:45-4:55 | H30: 7.5 | I30: Wk17. Strength/speed endurance.
B31: 6 x 2 min (sharpener) | C31: Intervals (VO2) | D31: 1.5 km easy + 2 strides | E31: 6 x 2 min quick, 2 min easy jog between. | F31: 1.5 km easy | G31: reps 4:35-4:45 | H31: 5 | I31: Wk19 taper - keep legs sharp, cut it if flat.
B32: TIME TRIALS, STRIDES & RACE
B33: Baseline 5K time trial | C33: Time trial | D33: 1.5 km easy + 4 strides | E33: 5 km at a hard, even, sustainable effort - record the time. | F33: 1.0 km easy | G33: max sustainable 5K effort | H33: 5 | I33: Wk1 (Fri 24 Jul). Result CALIBRATES every pace zone on Overview.
B34: Half-marathon time trial | C34: Time trial | D34: 1.0 km easy | E34: 21.1 km at hard/goal effort - your fitness checkpoint. | F34: walk / very easy | G34: ~5:23-5:32 target (sub-3:50 pace check) | H34: 21.1 | I34: Wk13 (Sat 17 Oct). Recomputes goal marathon pace (HM x ~2.11).
B35: Shakeout + strides | C35: Shakeout | D35: - | E35: Very easy jog + 4 x 20 s relaxed strides. Keep the legs turning over. | F35: - | G35: easy 6:10-6:40, strides relaxed | H35: 3 | I35: Wk21 (Tue). Nothing hard - just movement.
B36: Pre-race shakeout | C36: Shakeout | D36: - | E36: Very short easy jog + 2-3 short strides. Lay out kit, early night. | F36: - | G36: easy 6:10-6:40 | H36: 2.5 | I36: Wk21 (Fri, day before race).
B37: Marathon - race day | C37: Race | D37: arrive early, light jog + strides | E37: 42.2 km. Start conservative (~5:30-5:33), settle, negative-split if it is going well. | F37: walk, refuel | G37: goal ~5:27 (sub-3:50) | H37: 42.2 | I37: Wk21 (Sat 12 Dec). Trust the taper. Fuel every ~40 min.

Sheet Weekly Summary
A1: Week | B1: Phase | C1: Planned Sessions | D1: Completed Sessions | E1: Planned (km) | F1: Actual (km) | G1: Avg RPE | H1: Adherence
A2: 1 | B2: =INDEX('Weekly Plan'!$B$2:$B$999,MATCH(A2,'Weekly Plan'!$A$2:$A$999,0)) -> Base building | C2: =COUNTIFS('Weekly Plan'!$A$2:$A$999,A2,'Weekly Plan'!$F$2:$F$999,"<>Rest") -> 6 | D2: =COUNTIFS('Weekly Plan'!$A$2:$A$999,A2,'Weekly Plan'!$F$2:$F$999,"<>Rest",'Weekly Plan'!$L$2:$L$999,"Y") -> 5 | E2: =SUMIFS('Weekly Plan'!$H$2:$H$999,'Weekly Plan'!$A$2:$A$999,A2) -> 21 | F2: =SUMIFS('Weekly Plan'!$M$2:$M$999,'Weekly Plan'!$A$2:$A$999,A2) -> 21 | G2: =IFERROR(AVERAGEIFS('Weekly Plan'!$P$2:$P$999,'Weekly Plan'!$A$2:$A$999,A2),"") -> 4.2 | H2: =IFERROR(D2/C2,"") -> 0.83333333
A3: 2 | B3: =INDEX('Weekly Plan'!$B$2:$B$999,MATCH(A3,'Weekly Plan'!$A$2:$A$999,0)) -> Base building | C3: =COUNTIFS('Weekly Plan'!$A$2:$A$999,A3,'Weekly Plan'!$F$2:$F$999,"<>Rest") -> 8 | D3: =COUNTIFS('Weekly Plan'!$A$2:$A$999,A3,'Weekly Plan'!$F$2:$F$999,"<>Rest",'Weekly Plan'!$L$2:$L$999,"Y") -> 2 | E3: =SUMIFS('Weekly Plan'!$H$2:$H$999,'Weekly Plan'!$A$2:$A$999,A3) -> 29.5 | F3: =SUMIFS('Weekly Plan'!$M$2:$M$999,'Weekly Plan'!$A$2:$A$999,A3) -> 14 | G3: =IFERROR(AVERAGEIFS('Weekly Plan'!$P$2:$P$999,'Weekly Plan'!$A$2:$A$999,A3),"") -> 6.5 | H3: =IFERROR(D3/C3,"") -> 0.25
A4: 3 | B4: =INDEX('Weekly Plan'!$B$2:$B$999,MATCH(A4,'Weekly Plan'!$A$2:$A$999,0)) -> Base building | C4: =COUNTIFS('Weekly Plan'!$A$2:$A$999,A4,'Weekly Plan'!$F$2:$F$999,"<>Rest") -> 8 | D4: =COUNTIFS('Weekly Plan'!$A$2:$A$999,A4,'Weekly Plan'!$F$2:$F$999,"<>Rest",'Weekly Plan'!$L$2:$L$999,"Y") -> 0 | E4: =SUMIFS('Weekly Plan'!$H$2:$H$999,'Weekly Plan'!$A$2:$A$999,A4) -> 32.5 | F4: =SUMIFS('Weekly Plan'!$M$2:$M$999,'Weekly Plan'!$A$2:$A$999,A4) -> 0 | G4: =IFERROR(AVERAGEIFS('Weekly Plan'!$P$2:$P$999,'Weekly Plan'!$A$2:$A$999,A4),"") | H4: =IFERROR(D4/C4,"") -> 0
A5: 4 | B5: =INDEX('Weekly Plan'!$B$2:$B$999,MATCH(A5,'Weekly Plan'!$A$2:$A$999,0)) -> Base building | C5: =COUNTIFS('Weekly Plan'!$A$2:$A$999,A5,'Weekly Plan'!$F$2:$F$999,"<>Rest") -> 8 | D5: =COUNTIFS('Weekly Plan'!$A$2:$A$999,A5,'Weekly Plan'!$F$2:$F$999,"<>Rest",'Weekly Plan'!$L$2:$L$999,"Y") -> 0 | E5: =SUMIFS('Weekly Plan'!$H$2:$H$999,'Weekly Plan'!$A$2:$A$999,A5) -> 34.5 | F5: =SUMIFS('Weekly Plan'!$M$2:$M$999,'Weekly Plan'!$A$2:$A$999,A5) -> 0 | G5: =IFERROR(AVERAGEIFS('Weekly Plan'!$P$2:$P$999,'Weekly Plan'!$A$2:$A$999,A5),"") | H5: =IFERROR(D5/C5,"") -> 0
A6: 5 | B6: =INDEX('Weekly Plan'!$B$2:$B$999,MATCH(A6,'Weekly Plan'!$A$2:$A$999,0)) -> Base building | C6: =COUNTIFS('Weekly Plan'!$A$2:$A$999,A6,'Weekly Plan'!$F$2:$F$999,"<>Rest") -> 8 | D6: =COUNTIFS('Weekly Plan'!$A$2:$A$999,A6,'Weekly Plan'!$F$2:$F$999,"<>Rest",'Weekly Plan'!$L$2:$L$999,"Y") -> 0 | E6: =SUMIFS('Weekly Plan'!$H$2:$H$999,'Weekly Plan'!$A$2:$A$999,A6) -> 27.5 | F6: =SUMIFS('Weekly Plan'!$M$2:$M$999,'Weekly Plan'!$A$2:$A$999,A6) -> 0 | G6: =IFERROR(AVERAGEIFS('Weekly Plan'!$P$2:$P$999,'Weekly Plan'!$A$2:$A$999,A6),"") | H6: =IFERROR(D6/C6,"") -> 0
A7: 6 | B7: =INDEX('Weekly Plan'!$B$2:$B$999,MATCH(A7,'Weekly Plan'!$A$2:$A$999,0)) -> Base building | C7: =COUNTIFS('Weekly Plan'!$A$2:$A$999,A7,'Weekly Plan'!$F$2:$F$999,"<>Rest") -> 8 | D7: =COUNTIFS('Weekly Plan'!$A$2:$A$999,A7,'Weekly Plan'!$F$2:$F$999,"<>Rest",'Weekly Plan'!$L$2:$L$999,"Y") -> 0 | E7: =SUMIFS('Weekly Plan'!$H$2:$H$999,'Weekly Plan'!$A$2:$A$999,A7) -> 36.5 | F7: =SUMIFS('Weekly Plan'!$M$2:$M$999,'Weekly Plan'!$A$2:$A$999,A7) -> 0 | G7: =IFERROR(AVERAGEIFS('Weekly Plan'!$P$2:$P$999,'Weekly Plan'!$A$2:$A$999,A7),"") | H7: =IFERROR(D7/C7,"") -> 0
A8: 7 | B8: =INDEX('Weekly Plan'!$B$2:$B$999,MATCH(A8,'Weekly Plan'!$A$2:$A$999,0)) -> Base building | C8: =COUNTIFS('Weekly Plan'!$A$2:$A$999,A8,'Weekly Plan'!$F$2:$F$999,"<>Rest") -> 8 | D8: =COUNTIFS('Weekly Plan'!$A$2:$A$999,A8,'Weekly Plan'!$F$2:$F$999,"<>Rest",'Weekly Plan'!$L$2:$L$999,"Y") -> 0 | E8: =SUMIFS('Weekly Plan'!$H$2:$H$999,'Weekly Plan'!$A$2:$A$999,A8) -> 40.5 | F8: =SUMIFS('Weekly Plan'!$M$2:$M$999,'Weekly Plan'!$A$2:$A$999,A8) -> 0 | G8: =IFERROR(AVERAGEIFS('Weekly Plan'!$P$2:$P$999,'Weekly Plan'!$A$2:$A$999,A8),"") | H8: =IFERROR(D8/C8,"") -> 0
A9: 8 | B9: =INDEX('Weekly Plan'!$B$2:$B$999,MATCH(A9,'Weekly Plan'!$A$2:$A$999,0)) -> Aerobic build | C9: =COUNTIFS('Weekly Plan'!$A$2:$A$999,A9,'Weekly Plan'!$F$2:$F$999,"<>Rest") -> 9 | D9: =COUNTIFS('Weekly Plan'!$A$2:$A$999,A9,'Weekly Plan'!$F$2:$F$999,"<>Rest",'Weekly Plan'!$L$2:$L$999,"Y") -> 0 | E9: =SUMIFS('Weekly Plan'!$H$2:$H$999,'Weekly Plan'!$A$2:$A$999,A9) -> 50 | F9: =SUMIFS('Weekly Plan'!$M$2:$M$999,'Weekly Plan'!$A$2:$A$999,A9) -> 0 | G9: =IFERROR(AVERAGEIFS('Weekly Plan'!$P$2:$P$999,'Weekly Plan'!$A$2:$A$999,A9),"") | H9: =IFERROR(D9/C9,"") -> 0
A10: 9 | B10: =INDEX('Weekly Plan'!$B$2:$B$999,MATCH(A10,'Weekly Plan'!$A$2:$A$999,0)) -> Aerobic build | C10: =COUNTIFS('Weekly Plan'!$A$2:$A$999,A10,'Weekly Plan'!$F$2:$F$999,"<>Rest") -> 9 | D10: =COUNTIFS('Weekly Plan'!$A$2:$A$999,A10,'Weekly Plan'!$F$2:$F$999,"<>Rest",'Weekly Plan'!$L$2:$L$999,"Y") -> 0 | E10: =SUMIFS('Weekly Plan'!$H$2:$H$999,'Weekly Plan'!$A$2:$A$999,A10) -> 53 | F10: =SUMIFS('Weekly Plan'!$M$2:$M$999,'Weekly Plan'!$A$2:$A$999,A10) -> 0 | G10: =IFERROR(AVERAGEIFS('Weekly Plan'!$P$2:$P$999,'Weekly Plan'!$A$2:$A$999,A10),"") | H10: =IFERROR(D10/C10,"") -> 0
A11: 10 | B11: =INDEX('Weekly Plan'!$B$2:$B$999,MATCH(A11,'Weekly Plan'!$A$2:$A$999,0)) -> Aerobic build | C11: =COUNTIFS('Weekly Plan'!$A$2:$A$999,A11,'Weekly Plan'!$F$2:$F$999,"<>Rest") -> 9 | D11: =COUNTIFS('Weekly Plan'!$A$2:$A$999,A11,'Weekly Plan'!$F$2:$F$999,"<>Rest",'Weekly Plan'!$L$2:$L$999,"Y") -> 0 | E11: =SUMIFS('Weekly Plan'!$H$2:$H$999,'Weekly Plan'!$A$2:$A$999,A11) -> 41.5 | F11: =SUMIFS('Weekly Plan'!$M$2:$M$999,'Weekly Plan'!$A$2:$A$999,A11) -> 0 | G11: =IFERROR(AVERAGEIFS('Weekly Plan'!$P$2:$P$999,'Weekly Plan'!$A$2:$A$999,A11),"") | H11: =IFERROR(D11/C11,"") -> 0
A12: 11 | B12: =INDEX('Weekly Plan'!$B$2:$B$999,MATCH(A12,'Weekly Plan'!$A$2:$A$999,0)) -> Aerobic build | C12: =COUNTIFS('Weekly Plan'!$A$2:$A$999,A12,'Weekly Plan'!$F$2:$F$999,"<>Rest") -> 9 | D12: =COUNTIFS('Weekly Plan'!$A$2:$A$999,A12,'Weekly Plan'!$F$2:$F$999,"<>Rest",'Weekly Plan'!$L$2:$L$999,"Y") -> 0 | E12: =SUMIFS('Weekly Plan'!$H$2:$H$999,'Weekly Plan'!$A$2:$A$999,A12) -> 52 | F12: =SUMIFS('Weekly Plan'!$M$2:$M$999,'Weekly Plan'!$A$2:$A$999,A12) -> 0 | G12: =IFERROR(AVERAGEIFS('Weekly Plan'!$P$2:$P$999,'Weekly Plan'!$A$2:$A$999,A12),"") | H12: =IFERROR(D12/C12,"") -> 0
A13: 12 | B13: =INDEX('Weekly Plan'!$B$2:$B$999,MATCH(A13,'Weekly Plan'!$A$2:$A$999,0)) -> Aerobic build | C13: =COUNTIFS('Weekly Plan'!$A$2:$A$999,A13,'Weekly Plan'!$F$2:$F$999,"<>Rest") -> 9 | D13: =COUNTIFS('Weekly Plan'!$A$2:$A$999,A13,'Weekly Plan'!$F$2:$F$999,"<>Rest",'Weekly Plan'!$L$2:$L$999,"Y") -> 0 | E13: =SUMIFS('Weekly Plan'!$H$2:$H$999,'Weekly Plan'!$A$2:$A$999,A13) -> 55 | F13: =SUMIFS('Weekly Plan'!$M$2:$M$999,'Weekly Plan'!$A$2:$A$999,A13) -> 0 | G13: =IFERROR(AVERAGEIFS('Weekly Plan'!$P$2:$P$999,'Weekly Plan'!$A$2:$A$999,A13),"") | H13: =IFERROR(D13/C13,"") -> 0
... A22: 21 | B22: =INDEX('Weekly Plan'!$B$2:$B$999,MATCH(A22,'Weekly Plan'!$A$2:$A$999,0)) -> Taper | C22: =COUNTIFS('Weekly Plan'!$A$2:$A$999,A22,'Weekly Plan'!$F$2:$F$999,"<>Rest") -> 5 | D22: =COUNTIFS('Weekly Plan'!$A$2:$A$999,A22,'Weekly Plan'!$F$2:$F$999,"<>Rest",'Weekly Plan'!$L$2:$L$999,"Y") -> 0 | E22: =SUMIFS('Weekly Plan'!$H$2:$H$999,'Weekly Plan'!$A$2:$A$999,A22) -> 50.7 | F22: =SUMIFS('Weekly Plan'!$M$2:$M$999,'Weekly Plan'!$A$2:$A$999,A22) -> 0 | G22: =IFERROR(AVERAGEIFS('Weekly Plan'!$P$2:$P$999,'Weekly Plan'!$A$2:$A$999,A22),"") | H22: =IFERROR(D22/C22,"") -> 0
A24: Planned/Completed exclude Rest rows. Adherence = Completed / Planned sessions for the week.

Sheet Plan Changelog
A1: Date | B1: Week(s) affected | C1: Change made | D1: Reason | E1: Changed by
A2: 46224 | B2: All (1-21) | C2: Initial 21-week plan created | D2: Baseline plan for sub-4:00 goal: 6 training days/week, 1 rest, gym 3x/week (Legs/Push/Pull), Sun-Sat weeks with long run on Saturday | E2: Claude (initial build)
A3: 46226 | B3: All (1-21) | C3: Restructured gym day placement: Wed=Pull (was Push), Thu=Medium-long run (was Pull gym), Fri=Push (was Medium-long). Wk1: swapped Push/Pull only (Wed=Pull, Thu=Push) since Fri is baseline TT. | D3: Push and Pull were back-to-back (Wed/Thu) with no upper-body recovery. New spacing gives Push and Pull a full day apart. Push now sits closest to Saturday long run (least disruptive to running); Pull is furthest. Legs unchanged (Mon). | E3: Ricardo (via Claude)
A10: The adapt-training-plan skill logs an entry here every time it adjusts an upcoming week. Add your own rows too if you tweak things manually.
A11: 46227 | B11: Wk2-Wk21 (all unlogged weeks) | C11: Recalibrated Overview pace zones (Easy 6:00-6:30, Tempo 5:00-5:15, Intervals 4:25-4:40; MP unchanged) and refreshed all Workouts sheet target paces. | D11: Wk1 baseline 5K time trial: 5 km in 23:20 @ 4:40/km, RPE 6, felt Good. VDOT ~44 implies sub-4:00 is comfortably in reach; kept MP anchored to stated goal per user instruction. | E11: Claude (skill)
A12: 46227 | B12: Overview + Wk2-Wk21 (all unlogged weeks) | C12: RPE on baseline 5K corrected to 7. Pace zones re-eased slightly (Easy 6:10-6:40, Tempo 5:05-5:20, Intervals 4:30-4:45). Goal nudged sub-4:00 → sub-3:55 (5:34/km); MP band shifted to 5:30-5:40. Workouts sheet + race-day target updated to match. | D12: User adjusted baseline RPE 6→7 (harder than first logged), so 4:40/km reflects closer to real fitness — pulled paces back a notch from the aggressive VDOT read. User asked for a small, conservative goal move now with re-evaluation at Wk15 (post-Wk13 HM time trial). | E12: Claude (skill)
A13: 46227 | B13: Overview (framing only, no pace changes) | C13: Reframed goal cell: primary objective is FINISH HEALTHY (first marathon); current time goal sub-3:55; hard ceiling 3:30; next goal review after Wk13 HM time trial. | D13: User clarified priorities — this is his first marathon, injury-free finish comes before time. Recorded in project memory so every future adaptation biases conservative by default. | E13: Claude (skill)
A14: 46227 | B14: Overview + Workouts (MP band only) | C14: Goal shifted sub-3:55 → sub-3:50 (5:27/km). MP band on Overview C15 → 5:23-5:30. MP references in Workouts (medium-long+MP, long+MP, 3x8 cruise, HM target, race day) updated. Easy/Tempo/Intervals unchanged (fitness-calibrated, not goal-calibrated). | D14: User set the goal at 3:50 and closed the discussion. Primary objective (finish healthy) and ceiling (3:30) unchanged. | E14: Claude (skill)
